<mujocoinclude>
  <camera pos="0 0.5 1.5" name="topview" />
  <camera name="corner" mode="fixed" pos="-1.1 -0.4 0.6" xyaxes="-1 1 0 -0.2 -0.2 -1"/>
  <camera name="corner2" fovy="60" mode="fixed" pos="1.3 -0.2 1.1" euler="3.9 2.3 0.6"/>
  <camera name="corner3" fovy="45" mode="fixed" pos="0.9 0 1.5" euler="3.5 2.7 1"/>

  <body name="base" quat="0 0 0 -1" childclass="ur5e">
    <inertial mass="4.0" pos="0 0 0" diaginertia="0.00443333156 0.00443333156 0.0072"/>
    <geom mesh="base_0" material="black" class="visual"/>
    <geom mesh="base_1" material="jointgray" class="visual"/>
    <body name="shoulder_link" pos="0 0 0.163">
      <inertial mass="3.7" pos="0 0 0" diaginertia="0.0102675 0.0102675 0.00666"/>
      <joint name="shoulder_pan_joint" class="size3" axis="0 0 1"/>
      <geom mesh="shoulder_0" material="urblue" class="visual"/>
      <geom mesh="shoulder_1" material="black" class="visual"/>
      <geom mesh="shoulder_2" material="jointgray" class="visual"/>
      <geom class="collision" size="0.06 0.06" pos="0 0 -0.04"/>
      <body name="upper_arm_link" pos="0 0.138 0" quat="1 0 1 0">
        <inertial mass="8.393" pos="0 0 0.2125" diaginertia="0.133886 0.133886 0.0151074"/>
        <joint name="shoulder_lift_joint" class="size3"/>
        <geom mesh="upperarm_0" material="linkgray" class="visual"/>
        <geom mesh="upperarm_1" material="black" class="visual"/>
        <geom mesh="upperarm_2" material="jointgray" class="visual"/>
        <geom mesh="upperarm_3" material="urblue" class="visual"/>
        <geom class="collision" pos="0 -0.04 0" quat="1 1 0 0" size="0.06 0.06"/>
        <geom class="collision" size="0.05 0.2" pos="0 0 0.2"/>
        <body name="forearm_link" pos="0 -0.131 0.425">
          <inertial mass="2.275" pos="0 0 0.196" diaginertia="0.0311796 0.0311796 0.004095"/>
          <joint name="elbow_joint" class="size3_limited"/>
          <geom mesh="forearm_0" material="urblue" class="visual"/>
          <geom mesh="forearm_1" material="linkgray" class="visual"/>
          <geom mesh="forearm_2" material="black" class="visual"/>
          <geom mesh="forearm_3" material="jointgray" class="visual"/>
          <geom class="collision" pos="0 0.08 0" quat="1 1 0 0" size="0.055 0.06"/>
          <geom class="collision" size="0.038 0.19" pos="0 0 0.2"/>
          <body name="wrist_1_link" pos="0 0 0.392" quat="1 0 1 0">
            <inertial mass="1.219" pos="0 0.127 0" diaginertia="0.0025599 0.0025599 0.0021942"/>
            <joint name="wrist_1_joint" class="size1"/>
            <geom mesh="wrist1_0" material="black" class="visual"/>
            <geom mesh="wrist1_1" material="urblue" class="visual"/>
            <geom mesh="wrist1_2" material="jointgray" class="visual"/>
            <geom class="collision" pos="0 0.05 0" quat="1 1 0 0" size="0.04 0.07"/>
            <body name="wrist_2_link" pos="0 0.127 0">
              <inertial mass="1.219" pos="0 0 0.1" diaginertia="0.0025599 0.0025599 0.0021942"/>
              <joint name="wrist_2_joint" axis="0 0 1" class="size1"/>
              <geom mesh="wrist2_0" material="black" class="visual"/>
              <geom mesh="wrist2_1" material="urblue" class="visual"/>
              <geom mesh="wrist2_2" material="jointgray" class="visual"/>
              <geom class="collision" size="0.04 0.06" pos="0 0 0.04"/>
              <geom class="collision" pos="0 0.02 0.1" quat="1 1 0 0" size="0.04 0.04"/>
              <body name="wrist_3_link" pos="0 0 0.1">
                <inertial mass="0.1889" pos="0 0.0771683 0" quat="1 0 0 1"
                  diaginertia="0.000132134 9.90863e-05 9.90863e-05"/>
                <joint name="wrist_3_joint" class="size1"/>
                <geom material="linkgray" mesh="wrist3" class="visual"/>
                <geom class="eef_collision" pos="0 0.08 0" quat="1 1 0 0" size="0.04 0.02"/>
                <site name="attachment_site" pos="0 0.1 0" quat="-1 1 0 0"/>
                <body name="hand" pos="0 0.15 0" quat="1 0 0 1">
                  <camera name="behindGripper" mode="track" pos="0 0 -0.5" quat="0 1 0 0" fovy="60" />
                  <camera name="gripperPOV" mode="track" pos="0 -0.1 0" quat="-1 -1.3 0 0" fovy="90" />

                  <site name="endEffector" pos="0.04 0 0" size="0.01" rgba='1 1 1 0' />
                  <geom name="rail" type="box" pos="-0.05 0 0" density="7850" size="0.005 0.055 0.005" rgba="0.5 0.5 0.5 1.0" condim="3" friction="2 0.1 0.002" />

                  <body name="rightclaw" pos="0 -0.05 0">
                    <geom class="base_col" name="rightclaw_it" condim="4" margin="0.001" type="box" user="0" pos="0 0 0" size="0.045 0.003 0.015" rgba="1 1 1 1.0" />
                    <joint name="r_close" pos="0 0 0" axis="0 1 0" range= "0 0.04" armature="100" damping="1000" limited="true" type="slide"/>
                    <site name="rightEndEffector" pos="0.045 0 0" size="0.01" rgba="1.0 0.0 0.0 1.0"/>
                    <body name="rightpad" pos="0 .003 0">
                      <geom name="rightpad_geom" condim="4" margin="0.001" type="box" user="0" pos="0 0 0" size="0.045 0.003 0.015" rgba="1 1 1 1.0" solimp="0.95 0.99 0.01" solref="0.01 1" friction="2 0.1 0.002" contype="1" conaffinity="1" mass="1"/>
                    </body>
                  </body>

                  <body name="leftclaw" pos="0 0.05 0">
                    <geom class="base_col" name="leftclaw_it" condim="4" margin="0.001" type="box" user="0" pos="0 0 0" size="0.045 0.003 0.015" rgba="0 1 1 1.0" />
                    <joint name="l_close" pos="0 0 0" axis="0 1 0" range= "-0.03 0" armature="100" damping="1000" limited="true" type="slide"/>
                    <site name="leftEndEffector" pos="0.045 0 0" size="0.01" rgba="1.0 0.0 0.0 1.0"/>
                    <body name="leftpad" pos="0 -.003 0">
                      <geom name="leftpad_geom" condim="4" margin="0.001" type="box" user="0" pos="0 0 0" size="0.045 0.003 0.015" rgba="0 1 1 1.0" solimp="0.95 0.99 0.01" solref="0.01 1" friction="2 0.1 0.002" contype="1" conaffinity="1" />
                    </body>
                  </body>
                </body>
              </body>
            </body>
          </body>
        </body>
      </body>
    </body>
  </body>

  <body mocap="true" name="mocap" pos="0 0 0">
    <geom conaffinity="0" contype="0" pos="0 0 0" rgba="0.0 0.5 0.5 0" size="0.01" type="sphere"></geom>
    <site name="mocap" pos="0 0 0" rgba="0.0 0.5 0.5 0" size="0.01" type="sphere"></site>
  </body>

</mujocoinclude>