<mujocoinclude>
  <camera pos="0 0.5 1.5" name="topview" />
  <camera name="corner" mode="fixed" pos="-1.1 -0.4 0.6" xyaxes="-1 1 0 -0.2 -0.2 -1"/>
  <camera name="corner2" fovy="60" mode="fixed" pos="1.3 -0.2 1.1" euler="3.9 2.3 0.6"/>
  <camera name="corner3" fovy="45" mode="fixed" pos="0.9 0 1.5" euler="3.5 2.7 1"/>

  <body name="base" quat="0 0 0 -1" childclass="ur10e">
    <inertial mass="4.0" pos="0 0 0" diaginertia="0.0061063308908 0.0061063308908 0.01125"/>
    <geom mesh="base_0" material="black" class="visual"/>
    <geom mesh="base_1" material="jointgray" class="visual"/>
    <body name="shoulder_link" pos="0 0 0.181">
      <inertial pos="0 0 0" mass="7.778" diaginertia="0.0314743 0.0314743 0.0218756"/>
      <joint name="shoulder_pan_joint" class="size4" axis="0 0 1"/>
      <geom mesh="shoulder_0" material="urblue" class="visual"/>
      <geom mesh="shoulder_1" material="black" class="visual"/>
      <geom mesh="shoulder_2" material="jointgray" class="visual"/>
      <geom class="collision" size="0.078 0.08" pos="0 0 -0.05"/>
      <body name="upper_arm_link" pos="0 0.176 0" quat="1 0 1 0">
        <inertial pos="0 0 0.3065" mass="12.93" diaginertia="0.423074 0.423074 0.0363656"/>
        <joint name="shoulder_lift_joint" class="size4"/>
        <geom mesh="upperarm_0" material="black" class="visual"/>
        <geom mesh="upperarm_1" material="jointgray" class="visual"/>
        <geom mesh="upperarm_2" material="urblue" class="visual"/>
        <geom mesh="upperarm_3" material="linkgray" class="visual"/>
        <geom class="collision" pos="0 -0.05 0" quat="1 1 0 0" size="0.078 0.08"/>
        <geom class="collision" size="0.06 0.3" pos="0 0 0.3"/>
        <body name="forearm_link" pos="0 -0.137 0.613">
          <inertial pos="0 0 0.2855" mass="3.87" diaginertia="0.11059 0.11059 0.0108844"/>
          <joint name="elbow_joint" class="size3_limited"/>
          <geom mesh="forearm_0" material="urblue" class="visual"/>
          <geom mesh="forearm_1" material="black" class="visual"/>
          <geom mesh="forearm_2" material="jointgray" class="visual"/>
          <geom mesh="forearm_3" material="linkgray" class="visual"/>
          <geom class="collision" pos="0 0.08 0" quat="1 1 0 0" size="0.058 0.065"/>
          <geom class="collision" size="0.043 0.28" pos="0 0 0.29"/>
          <body name="wrist_1_link" pos="0 0 0.571" quat="1 0 1 0">
            <inertial pos="0 0.135 0" quat="0.5 0.5 -0.5 0.5" mass="1.96"
              diaginertia="0.0055125 0.00510825 0.00510825"/>
            <joint name="wrist_1_joint" class="size2"/>
            <geom mesh="wrist1_0" material="black" class="visual"/>
            <geom mesh="wrist1_1" material="urblue" class="visual"/>
            <geom mesh="wrist1_2" material="jointgray" class="visual"/>
            <geom class="collision" pos="0 0.06 0" quat="1 1 0 0" size="0.05 0.07"/>
            <body name="wrist_2_link" pos="0 0.135 0">
              <inertial pos="0 0 0.12" quat="0.5 0.5 -0.5 0.5" mass="1.96"
                diaginertia="0.0055125 0.00510825 0.00510825"/>
              <joint name="wrist_2_joint" axis="0 0 1" class="size2"/>
              <geom mesh="wrist2_0" material="black" class="visual"/>
              <geom mesh="wrist2_1" material="urblue" class="visual"/>
              <geom mesh="wrist2_2" material="jointgray" class="visual"/>
              <geom class="collision" size="0.046 0.065" pos="0 0 0.05"/>
              <geom class="collision" pos="0 0.028 0.12" quat="1 1 0 0" size="0.046 0.043"/>
              <body name="wrist_3_link" pos="0 0 0.12">
                <inertial pos="0 0.092 0" quat="0 1 -1 0" mass="0.202"
                  diaginertia="0.000204525 0.000144346 0.000144346"/>
                <joint name="wrist_3_joint" class="size2"/>
                <geom material="linkgray" mesh="wrist3" class="visual"/>
                <geom class="eef_collision" pos="0 0.097 0" quat="1 1 0 0" size="0.046 0.02"/>
                <site name="attachment_site" pos="0 0.1 0" quat="-1 1 0 0"/>
                <!-- 夹爪连接 - 注意正确的四元数 -->
                <body name="hand" pos="0 0.15 0" quat="1 0 0 1">
                  <camera name="behindGripper" mode="track" pos="0 0 -0.5" quat="0 1 0 0" fovy="60" />
                  <camera name="gripperPOV" mode="track" pos="0 -0.1 0" quat="-1 -1.3 0 0" fovy="90" />

                  <site name="endEffector" pos="0.04 0 0" size="0.01" rgba='1 1 1 0' />
                  <geom name="rail" type="box" pos="-0.05 0 0" density="7850" size="0.005 0.055 0.005" rgba="0.5 0.5 0.5 1.0" condim="3" friction="2 0.1 0.002" />

                  <body name="rightclaw" pos="0 -0.05 0">
                    <geom class="base_col" name="rightclaw_it" condim="4" margin="0.001" type="box" user="0" pos="0 0 0" size="0.045 0.003 0.015" rgba="1 1 1 1.0" />
                    <joint name="r_close" pos="0 0 0" axis="0 1 0" range= "0 0.04" armature="100" damping="1000" limited="true" type="slide"/>
                    <!-- <joint name="r_close" pos="0 0 0" axis="0 1 0" range= "0 0.03" armature="100" damping="1000" limited="true"  type="slide"/>  -->

                    <site name="rightEndEffector" pos="0.045 0 0" size="0.01" rgba="1.0 0.0 0.0 1.0"/>
                    <body name="rightpad" pos="0 .003 0">
                      <geom name="rightpad_geom" condim="4" margin="0.001" type="box" user="0" pos="0 0 0" size="0.045 0.003 0.015" rgba="1 1 1 1.0" solimp="0.95 0.99 0.01" solref="0.01 1" friction="2 0.1 0.002" contype="1" conaffinity="1" mass="1"/>
                    </body>
                  </body>

                  <body name="leftclaw" pos="0 0.05 0">
                    <geom class="base_col" name="leftclaw_it" condim="4" margin="0.001" type="box" user="0" pos="0 0 0" size="0.045 0.003 0.015" rgba="0 1 1 1.0" />
                    <joint name="l_close" pos="0 0 0" axis="0 1 0" range= "-0.03 0" armature="100" damping="1000" limited="true" type="slide"/>
                    <site name="leftEndEffector" pos="0.045 0 0" size="0.01" rgba="1.0 0.0 0.0 1.0"/>
                    <body name="leftpad" pos="0 -.003 0">
                      <geom name="leftpad_geom" condim="4" margin="0.001" type="box" user="0" pos="0 0 0" size="0.045 0.003 0.015" rgba="0 1 1 1.0" solimp="0.95 0.99 0.01" solref="0.01 1" friction="2 0.1 0.002" contype="1" conaffinity="1" />
                    </body>
                  </body>
                </body>
              </body>
            </body>
          </body>
        </body>
      </body>
    </body>
  </body>

  <body mocap="true" name="mocap" pos="0 0 0">
    <geom conaffinity="0" contype="0" pos="0 0 0" rgba="0.0 0.5 0.5 0" size="0.01" type="sphere"></geom>
    <site name="mocap" pos="0 0 0" rgba="0.0 0.5 0.5 0" size="0.01" type="sphere"></site>
  </body>

</mujocoinclude>